<mujoco model="go2">
    <compiler angle="degree" coordinate="local" inertiafromgeom="auto"/>
    <option timestep="0.002" gravity="0 0 -9.81" integrator="RK4"/>

    <default>
        <joint limited="true" damping="0.2" armature="0.01" type="hinge"/>
        <geom type="capsule" size="0.025" friction="1.0 0.1 0.1" condim="3"
              solref="0.01 1" solimp="0.95 0.99 0.001" rgba="0.8 0.7 0.5 1.0"/>
        <motor ctrllimited="true" ctrlrange="-1 1"/>
    </default>

    <worldbody>
        <!-- Torso -->
        <body name="torso" pos="0 0 0.3">
            <geom type="box" size="0.2 0.07 0.04" mass="5.0"/>

            <!-- Front Right Leg -->
            <body name="FR_hip" pos="0.18 -0.05 0">
                <joint name="FR_hip_joint" axis="1 0 0" range="-45 45"/>
                <geom fromto="0 0 0 0 0.05 0" size="0.025"/>
                <body name="FR_thigh" pos="0 0.05 0">
                    <joint name="FR_thigh_joint" axis="0 1 0" range="-90 90"/>
                    <geom fromto="0 0 0 0 0 -0.2" size="0.025"/>
                    <body name="FR_calf" pos="0 0 -0.2">
                        <joint name="FR_calf_joint" axis="0 1 0" range="-150 -30"/>
                        <geom fromto="0 0 0 0 0 -0.2" size="0.025"/>
                        <geom type="sphere" size="0.03" pos="0 0 -0.2" rgba="0.2 0.2 0.2 1.0"/>
                    </body>
                </body>
            </body>

            <!-- Front Left Leg -->
            <body name="FL_hip" pos="0.18 0.05 0">
                <joint name="FL_hip_joint" axis="1 0 0" range="-45 45"/>
                <geom fromto="0 0 0 0 -0.05 0" size="0.025"/>
                <body name="FL_thigh" pos="0 -0.05 0">
                    <joint name="FL_thigh_joint" axis="0 1 0" range="-90 90"/>
                    <geom fromto="0 0 0 0 0 -0.2" size="0.025"/>
                    <body name="FL_calf" pos="0 0 -0.2">
                        <joint name="FL_calf_joint" axis="0 1 0" range="-150 -30"/>
                        <geom fromto="0 0 0 0 0 -0.2" size="0.025"/>
                        <geom type="sphere" size="0.03" pos="0 0 -0.2" rgba="0.2 0.2 0.2 1.0"/>
                    </body>
                </body>
            </body>

            <!-- Rear Right Leg -->
            <body name="RR_hip" pos="-0.18 -0.05 0">
                <joint name="RR_hip_joint" axis="1 0 0" range="-45 45"/>
                <geom fromto="0 0 0 0 0.05 0" size="0.025"/>
                <body name="RR_thigh" pos="0 0.05 0">
                    <joint name="RR_thigh_joint" axis="0 1 0" range="-90 90"/>
                    <geom fromto="0 0 0 0 0 -0.2" size="0.025"/>
                    <body name="RR_calf" pos="0 0 -0.2">
                        <joint name="RR_calf_joint" axis="0 1 0" range="-150 -30"/>
                        <geom fromto="0 0 0 0 0 -0.2" size="0.025"/>
                        <geom type="sphere" size="0.03" pos="0 0 -0.2" rgba="0.2 0.2 0.2 1.0"/>
                    </body>
                </body>
            </body>

            <!-- Rear Left Leg -->
            <body name="RL_hip" pos="-0.18 0.05 0">
                <joint name="RL_hip_joint" axis="1 0 0" range="-45 45"/>
                <geom fromto="0 0 0 0 -0.05 0" size="0.025"/>
                <body name="RL_thigh" pos="0 -0.05 0">
                    <joint name="RL_thigh_joint" axis="0 1 0" range="-90 90"/>
                    <geom fromto="0 0 0 0 0 -0.2" size="0.025"/>
                    <body name="RL_calf" pos="0 0 -0.2">
                        <joint name="RL_calf_joint" axis="0 1 0" range="-150 -30"/>
                        <geom fromto="0 0 0 0 0 -0.2" size="0.025"/>
                        <geom type="sphere" size="0.03" pos="0 0 -0.2" rgba="0.2 0.2 0.2 1.0"/>
                    </body>
                </body>
            </body>

        </body>
    </worldbody>

    <actuator>
        <motor joint="FR_hip_joint" gear="20"/>
        <motor joint="FR_thigh_joint" gear="30"/>
        <motor joint="FR_calf_joint" gear="30"/>

        <motor joint="FL_hip_joint" gear="20"/>
        <motor joint="FL_thigh_joint" gear="30"/>
        <motor joint="FL_calf_joint" gear="30"/>

        <motor joint="RR_hip_joint" gear="20"/>
        <motor joint="RR_thigh_joint" gear="30"/>
        <motor joint="RR_calf_joint" gear="30"/>

        <motor joint="RL_hip_joint" gear="20"/>
        <motor joint="RL_thigh_joint" gear="30"/>
        <motor joint="RL_calf_joint" gear="30"/>
    </actuator>

</mujoco>
