<mujoco model="invpend">
    <compiler angle="degree"/>
    <option gravity="0 0 -9.81"/>

    <worldbody>
        <body name="base" pos="0 0 0.1">
            <geom type="box" size="0.1 0.1 0.1" rgba="0.3 0.3 0.3 1"/>
            
            <body name="pend" pos="0 0 0.1">
                <joint name="hinge" type="hinge" axis="0 1 0" limited="false" damping="0.01"/>
                <geom type="capsule" fromto="0 0 0 0 0 1" size="0.02" rgba="0.8 0.2 0.2 1"/>
                <geom type="capsule" fromto="0 0 0 0 0 1" size="0.02" rgba="0.8 0.2 0.2 1" mass="0.5"/>

            </body>
        </body>
    </worldbody>
</mujoco>
